DEBUG 2023-04-05 20:49:53,723 views 15132 42596 Debug message
DEBUG 2023-04-05 20:49:55,029 views 15132 42596 Debug message
DEBUG 2023-04-05 20:49:55,732 views 15132 42596 Debug message
DEBUG 2023-04-05 20:49:56,320 views 15132 42596 Debug message
DEBUG 2023-04-05 20:49:56,921 views 15132 42596 Debug message
DEBUG 2023-04-05 20:49:57,396 views 15132 42596 Debug message
DEBUG 2023-04-05 20:52:23,997 views 32584 8904 Debug message
ERROR 2023-04-05 20:52:24,067 log 32584 8904 Internal Server Error: /
Traceback (most recent call last):
  File "C:\Users\ILYA\AppData\Local\Packages\PythonSoftwareFoundation.Python.3.10_qbz5n2kfra8p0\LocalCache\local-packages\Python310\site-packages\django\core\handlers\exception.py", line 55, in inner
    response = get_response(request)
  File "C:\Users\ILYA\AppData\Local\Packages\PythonSoftwareFoundation.Python.3.10_qbz5n2kfra8p0\LocalCache\local-packages\Python310\site-packages\django\core\handlers\base.py", line 197, in _get_response
    response = wrapped_callback(request, *callback_args, **callback_kwargs)
  File "C:\Users\ILYA\Desktop\univer\site\mySite\main\views.py", line 19, in news
    all_news = New.objects.get(id = 0)
  File "C:\Users\ILYA\AppData\Local\Packages\PythonSoftwareFoundation.Python.3.10_qbz5n2kfra8p0\LocalCache\local-packages\Python310\site-packages\django\db\models\manager.py", line 85, in manager_method
    return getattr(self.get_queryset(), name)(*args, **kwargs)
  File "C:\Users\ILYA\AppData\Local\Packages\PythonSoftwareFoundation.Python.3.10_qbz5n2kfra8p0\LocalCache\local-packages\Python310\site-packages\django\db\models\query.py", line 650, in get
    raise self.model.DoesNotExist(
main.models.New.DoesNotExist: New matching query does not exist.
ERROR 2023-04-05 20:52:24,068 basehttp 32584 8904 "GET / HTTP/1.1" 500 83613
DEBUG 2023-04-05 20:52:25,735 views 32584 8904 Debug message
ERROR 2023-04-05 20:52:25,791 log 32584 8904 Internal Server Error: /
Traceback (most recent call last):
  File "C:\Users\ILYA\AppData\Local\Packages\PythonSoftwareFoundation.Python.3.10_qbz5n2kfra8p0\LocalCache\local-packages\Python310\site-packages\django\core\handlers\exception.py", line 55, in inner
    response = get_response(request)
  File "C:\Users\ILYA\AppData\Local\Packages\PythonSoftwareFoundation.Python.3.10_qbz5n2kfra8p0\LocalCache\local-packages\Python310\site-packages\django\core\handlers\base.py", line 197, in _get_response
    response = wrapped_callback(request, *callback_args, **callback_kwargs)
  File "C:\Users\ILYA\Desktop\univer\site\mySite\main\views.py", line 19, in news
    all_news = New.objects.get(id = 0)
  File "C:\Users\ILYA\AppData\Local\Packages\PythonSoftwareFoundation.Python.3.10_qbz5n2kfra8p0\LocalCache\local-packages\Python310\site-packages\django\db\models\manager.py", line 85, in manager_method
    return getattr(self.get_queryset(), name)(*args, **kwargs)
  File "C:\Users\ILYA\AppData\Local\Packages\PythonSoftwareFoundation.Python.3.10_qbz5n2kfra8p0\LocalCache\local-packages\Python310\site-packages\django\db\models\query.py", line 650, in get
    raise self.model.DoesNotExist(
main.models.New.DoesNotExist: New matching query does not exist.
ERROR 2023-04-05 20:52:25,792 basehttp 32584 8904 "GET / HTTP/1.1" 500 83613
ERROR 2023-04-05 21:15:14,155 log 18780 21964 Internal Server Error: /
Traceback (most recent call last):
  File "C:\Users\ILYA\AppData\Local\Packages\PythonSoftwareFoundation.Python.3.10_qbz5n2kfra8p0\LocalCache\local-packages\Python310\site-packages\django\core\handlers\exception.py", line 55, in inner
    response = get_response(request)
  File "C:\Users\ILYA\AppData\Local\Packages\PythonSoftwareFoundation.Python.3.10_qbz5n2kfra8p0\LocalCache\local-packages\Python310\site-packages\django\core\handlers\base.py", line 197, in _get_response
    response = wrapped_callback(request, *callback_args, **callback_kwargs)
  File "C:\Users\ILYA\Desktop\univer\site\mySite\main\views.py", line 16, in news
    all_news = New.objects.get(id = 0)
  File "C:\Users\ILYA\AppData\Local\Packages\PythonSoftwareFoundation.Python.3.10_qbz5n2kfra8p0\LocalCache\local-packages\Python310\site-packages\django\db\models\manager.py", line 85, in manager_method
    return getattr(self.get_queryset(), name)(*args, **kwargs)
  File "C:\Users\ILYA\AppData\Local\Packages\PythonSoftwareFoundation.Python.3.10_qbz5n2kfra8p0\LocalCache\local-packages\Python310\site-packages\django\db\models\query.py", line 650, in get
    raise self.model.DoesNotExist(
main.models.New.DoesNotExist: New matching query does not exist.
ERROR 2023-04-05 21:15:14,157 basehttp 18780 21964 "GET / HTTP/1.1" 500 83041
DEBUG 2023-04-05 21:15:50,864 views 44988 37684 —Œ«ƒ¿Õ¿ ∆¿ÀŒ¡¿
DEBUG 2023-04-05 21:17:14,377 views 44988 37684 —Œ«ƒ¿Õ¿ ∆¿ÀŒ¡¿
DEBUG 2023-04-05 21:18:02,363 views 44988 37684 —Œ«ƒ¿Õ¿ ∆¿ÀŒ¡¿
DEBUG 2023-04-05 21:18:03,669 views 44988 37684 —Œ«ƒ¿Õ¿ ∆¿ÀŒ¡¿
DEBUG 2023-04-05 21:21:00,298 views 44988 55724 —Œ«ƒ¿Õ œŒÀ‹«Œ¬¿“≈À‹
DEBUG 2023-04-05 21:21:14,144 views 44988 55724 œŒÀ‹«Œ¬¿“≈À‹ —“¿À ¿ƒÃ»ÕŒÃ
DEBUG 2023-04-05 21:21:59,713 views 44988 55724 —Œ«ƒ¿Õ œŒÀ‹«Œ¬¿“≈À‹
DEBUG 2023-04-05 21:22:06,351 views 44988 55724 œŒÀ‹«Œ¬¿“≈À‹ —“¿À ¿ƒÃ»ÕŒÃ
